Workbook

Sheet CORRESPONDENCIA
F3: COMPOSIÇÃO ANALÍTICA | H3: NBR 15965
A4: Subgrupo | C4: Código da Composição | E4: Descrição SICRO | F4: Código do Insumo | G4: Descrição do Insumo | H4: Classificação NBR 15965 | I4: Nível 1 | J4: Nível 2 | K4: Nível 3 | L4: Nível 4 | M4: Nível 5 | N4: Nível 6 | O4: Nível 7
A5: 2.1.1 | B5: Desmatamento, destocamento e limpeza-área com árvores de diâmetro até 0, 15 m | C5: 5501700 | D5: =A5 -> 2.1.1 | E5: Desmatamento, destocamento e limpeza-área com árvores de diâmetro até 0, 15 m
F6: E9541 | G6: Trator sobre esteiras com lâmina - 259 kW | H6: =VLOOKUP(G6,'insumos terrapl'!$C$3:$K$47,2,0) -> 2Q 62 30 02 14 00 00 | I6: =VLOOKUP(G6,'insumos terrapl'!$C$3:$K$47,3,0) -> 2Q | J6: =VLOOKUP(G6,'insumos terrapl'!$C$3:$K$47,4,0) -> 62 | K6: =VLOOKUP(G6,'insumos terrapl'!$C$3:$K$47,5,0) -> 30 | L6: =VLOOKUP(G6,'insumos terrapl'!$C$3:$K$47,6,0) -> 02 | M6: =VLOOKUP(G6,'insumos terrapl'!$C$3:$K$47,7,0) -> 14 | N6: =VLOOKUP(G6,'insumos terrapl'!$C$3:$K$47,8,0) -> 00 | O6: =VLOOKUP(G6,'insumos terrapl'!$C$3:$K$47,9,0) -> 00
F7: P9824 | G7: Servente | H7: =VLOOKUP(G7,'insumos terrapl'!$C$3:$K$47,2,0) -> 2N 20 14 08 00 00 00 | I7: =VLOOKUP(G7,'insumos terrapl'!$C$3:$K$47,3,0) -> 2N | J7: =VLOOKUP(G7,'insumos terrapl'!$C$3:$K$47,4,0) -> 20 | K7: =VLOOKUP(G7,'insumos terrapl'!$C$3:$K$47,5,0) -> 14 | L7: =VLOOKUP(G7,'insumos terrapl'!$C$3:$K$47,6,0) -> 08 | M7: =VLOOKUP(G7,'insumos terrapl'!$C$3:$K$47,7,0) -> 00 | N7: =VLOOKUP(G7,'insumos terrapl'!$C$3:$K$47,8,0) -> 00 | O7: =VLOOKUP(G7,'insumos terrapl'!$C$3:$K$47,9,0) -> 00
A9: 2.1.2 | B9: Destocamento de árvores de diâmetro superior a 0,15m | C9: 5501701 | D9: =A9 -> 2.1.2 | E9: Destocamento de árvores de diâmetro de 0,15 a 0,30 m | F9: 5501701
F10: E9541 | G10: Trator sobre esteiras com lâmina - 259 kW | H10: =VLOOKUP(G10,'insumos terrapl'!$C$3:$K$47,2,0) -> 2Q 62 30 02 14 00 00 | I10: =VLOOKUP(G10,'insumos terrapl'!$C$3:$K$47,3,0) -> 2Q | J10: =VLOOKUP(G10,'insumos terrapl'!$C$3:$K$47,4,0) -> 62 | K10: =VLOOKUP(G10,'insumos terrapl'!$C$3:$K$47,5,0) -> 30 | L10: =VLOOKUP(G10,'insumos terrapl'!$C$3:$K$47,6,0) -> 02 | M10: =VLOOKUP(G10,'insumos terrapl'!$C$3:$K$47,7,0) -> 14 | N10: =VLOOKUP(G10,'insumos terrapl'!$C$3:$K$47,8,0) -> 00 | O10: =VLOOKUP(G10,'insumos terrapl'!$C$3:$K$47,9,0) -> 00
F11: P9824 | G11: Servente | H11: =VLOOKUP(G11,'insumos terrapl'!$C$3:$K$47,2,0) -> 2N 20 14 08 00 00 00 | I11: =VLOOKUP(G11,'insumos terrapl'!$C$3:$K$47,3,0) -> 2N | J11: =VLOOKUP(G11,'insumos terrapl'!$C$3:$K$47,4,0) -> 20 | K11: =VLOOKUP(G11,'insumos terrapl'!$C$3:$K$47,5,0) -> 14 | L11: =VLOOKUP(G11,'insumos terrapl'!$C$3:$K$47,6,0) -> 08 | M11: =VLOOKUP(G11,'insumos terrapl'!$C$3:$K$47,7,0) -> 00 | N11: =VLOOKUP(G11,'insumos terrapl'!$C$3:$K$47,8,0) -> 00 | O11: =VLOOKUP(G11,'insumos terrapl'!$C$3:$K$47,9,0) -> 00
C13: 5501702 | D13: =A9 -> 2.1.2 | E13: Destocamento de árvores de diâmetro superior a 0, 30 m | F13: 5501702
F14: E9541 | G14: Trator sobre esteiras com lâmina - 259 kW | H14: =VLOOKUP(G14,'insumos terrapl'!$C$3:$K$47,2,0) -> 2Q 62 30 02 14 00 00 | I14: =VLOOKUP(G14,'insumos terrapl'!$C$3:$K$47,3,0) -> 2Q | J14: =VLOOKUP(G14,'insumos terrapl'!$C$3:$K$47,4,0) -> 62 | K14: =VLOOKUP(G14,'insumos terrapl'!$C$3:$K$47,5,0) -> 30 | L14: =VLOOKUP(G14,'insumos terrapl'!$C$3:$K$47,6,0) -> 02 | M14: =VLOOKUP(G14,'insumos terrapl'!$C$3:$K$47,7,0) -> 14 | N14: =VLOOKUP(G14,'insumos terrapl'!$C$3:$K$47,8,0) -> 00 | O14: =VLOOKUP(G14,'insumos terrapl'!$C$3:$K$47,9,0) -> 00
F15: P9824 | G15: Servente | H15: =VLOOKUP(G15,'insumos terrapl'!$C$3:$K$47,2,0) -> 2N 20 14 08 00 00 00 | I15: =VLOOKUP(G15,'insumos terrapl'!$C$3:$K$47,3,0) -> 2N | J15: =VLOOKUP(G15,'insumos terrapl'!$C$3:$K$47,4,0) -> 20 | K15: =VLOOKUP(G15,'insumos terrapl'!$C$3:$K$47,5,0) -> 14 | L15: =VLOOKUP(G15,'insumos terrapl'!$C$3:$K$47,6,0) -> 08 | M15: =VLOOKUP(G15,'insumos terrapl'!$C$3:$K$47,7,0) -> 00 | N15: =VLOOKUP(G15,'insumos terrapl'!$C$3:$K$47,8,0) -> 00 | O15: =VLOOKUP(G15,'insumos terrapl'!$C$3:$K$47,9,0) -> 00
A17: 2.1.3 | B17: Limpeza mecanizada da camada vegetal | C17: 5502985 | D17: =A17 -> 2.1.3 | E17: Limpeza mecanizada da camada vegetal
F18: E9540 | G18: Trator sobre esteiras com lâmina - 127 kW | H18: =VLOOKUP(G18,'insumos terrapl'!$C$3:$K$47,2,0) -> 2Q 62 30 02 14 00 00 | I18: =VLOOKUP(G18,'insumos terrapl'!$C$3:$K$47,3,0) -> 2Q | J18: =VLOOKUP(G18,'insumos terrapl'!$C$3:$K$47,4,0) -> 62 | K18: =VLOOKUP(G18,'insumos terrapl'!$C$3:$K$47,5,0) -> 30 | L18: =VLOOKUP(G18,'insumos terrapl'!$C$3:$K$47,6,0) -> 02 | M18: =VLOOKUP(G18,'insumos terrapl'!$C$3:$K$47,7,0) -> 14 | N18: =VLOOKUP(G18,'insumos terrapl'!$C$3:$K$47,8,0) -> 00 | O18: =VLOOKUP(G18,'insumos terrapl'!$C$3:$K$47,9,0) -> 00
F19: P9824 | G19: Servente | H19: =VLOOKUP(G19,'insumos terrapl'!$C$3:$K$47,2,0) -> 2N 20 14 08 00 00 00 | I19: =VLOOKUP(G19,'insumos terrapl'!$C$3:$K$47,3,0) -> 2N | J19: =VLOOKUP(G19,'insumos terrapl'!$C$3:$K$47,4,0) -> 20 | K19: =VLOOKUP(G19,'insumos terrapl'!$C$3:$K$47,5,0) -> 14 | L19: =VLOOKUP(G19,'insumos terrapl'!$C$3:$K$47,6,0) -> 08 | M19: =VLOOKUP(G19,'insumos terrapl'!$C$3:$K$47,7,0) -> 00 | N19: =VLOOKUP(G19,'insumos terrapl'!$C$3:$K$47,8,0) -> 00 | O19: =VLOOKUP(G19,'insumos terrapl'!$C$3:$K$47,9,0) -> 00
A20: 2.2.1 | B20: Expurgo de jazida | C20: 5502986 | D20: =A20 -> 2.2.1 | E20: Expurgo de jazida | F20: 5502986
F21: E9540 | G21: Trator sobre esteiras com lâmina - 127 kW | H21: =VLOOKUP(G21,'insumos terrapl'!$C$3:$K$47,2,0) -> 2Q 62 30 02 14 00 00 | I21: =VLOOKUP(G21,'insumos terrapl'!$C$3:$K$47,3,0) -> 2Q | J21: =VLOOKUP(G21,'insumos terrapl'!$C$3:$K$47,4,0) -> 62 | K21: =VLOOKUP(G21,'insumos terrapl'!$C$3:$K$47,5,0) -> 30 | L21: =VLOOKUP(G21,'insumos terrapl'!$C$3:$K$47,6,0) -> 02 | M21: =VLOOKUP(G21,'insumos terrapl'!$C$3:$K$47,7,0) -> 14 | N21: =VLOOKUP(G21,'insumos terrapl'!$C$3:$K$47,8,0) -> 00 | O21: =VLOOKUP(G21,'insumos terrapl'!$C$3:$K$47,9,0) -> 00
F22: P9824 | G22: Servente | H22: =VLOOKUP(G22,'insumos terrapl'!$C$3:$K$47,2,0) -> 2N 20 14 08 00 00 00 | I22: =VLOOKUP(G22,'insumos terrapl'!$C$3:$K$47,3,0) -> 2N | J22: =VLOOKUP(G22,'insumos terrapl'!$C$3:$K$47,4,0) -> 20 | K22: =VLOOKUP(G22,'insumos terrapl'!$C$3:$K$47,5,0) -> 14 | L22: =VLOOKUP(G22,'insumos terrapl'!$C$3:$K$47,6,0) -> 08 | M22: =VLOOKUP(G22,'insumos terrapl'!$C$3:$K$47,7,0) -> 00 | N22: =VLOOKUP(G22,'insumos terrapl'!$C$3:$K$47,8,0) -> 00 | O22: =VLOOKUP(G22,'insumos terrapl'!$C$3:$K$47,9,0) -> 00
A24: 2.3.1 | B24: Manutenção de caminhos de serviço | C24: 5503018 | D24: =A24 -> 2.3.1 | E24: Manutenção de caminhos de serviço | F24: 5503018
F25: E9524 | G25: Motoniveladora - 93 kW | H25: =VLOOKUP(G25,'insumos terrapl'!$C$3:$K$47,2,0) -> 2Q 62 30 06 02 00 00 | I25: =VLOOKUP(G25,'insumos terrapl'!$C$3:$K$47,3,0) -> 2Q | J25: =VLOOKUP(G25,'insumos terrapl'!$C$3:$K$47,4,0) -> 62 | K25: =VLOOKUP(G25,'insumos terrapl'!$C$3:$K$47,5,0) -> 30 | L25: =VLOOKUP(G25,'insumos terrapl'!$C$3:$K$47,6,0) -> 06 | M25: =VLOOKUP(G25,'insumos terrapl'!$C$3:$K$47,7,0) -> 02 | N25: =VLOOKUP(G25,'insumos terrapl'!$C$3:$K$47,8,0) -> 00 | O25: =VLOOKUP(G25,'insumos terrapl'!$C$3:$K$47,9,0) -> 00
A27: 2.3.2 | B27: Umedecimento de caminho de serviço | C27: 5503020 | D27: =A27 -> 2.3.2 | E27: Umedecimento de caminho de serviço | F27: 5503020
F28: E9571 | G28: Caminhão tanque com capacidade de 10.000 l - 188 kW | H28: =VLOOKUP(G28,'insumos terrapl'!$C$3:$K$47,2,0) -> 2Q 66 06 26 00 00 00 | I28: =VLOOKUP(G28,'insumos terrapl'!$C$3:$K$47,3,0) -> 2Q | J28: =VLOOKUP(G28,'insumos terrapl'!$C$3:$K$47,4,0) -> 66 | K28: =VLOOKUP(G28,'insumos terrapl'!$C$3:$K$47,5,0) -> 06 | L28: =VLOOKUP(G28,'insumos terrapl'!$C$3:$K$47,6,0) -> 26 | M28: =VLOOKUP(G28,'insumos terrapl'!$C$3:$K$47,7,0) -> 00 | N28: =VLOOKUP(G28,'insumos terrapl'!$C$3:$K$47,8,0) -> 00 | O28: =VLOOKUP(G28,'insumos terrapl'!$C$3:$K$47,9,0) -> 00
A30: 2.4.1 | B30: Escavação mecânica com retroescavadeira em material de 1ª categoria | C30: 5501706 | D30: =A30 -> 2.4.1 | E30: Escavação mecânica com retroescavadeira em material de 1ª categoria | F30: 5501706
F31: E9526 | G31: Retroescavadeira de pneus - capacidade da caçamba da pá-carregadeira de 0,76 m³ e da retroescavadeira de 0,29 m³ - 58 kW | H31: =VLOOKUP(G31,'insumos terrapl'!$C$3:$K$47,2,0) -> 2Q 62 06 02 00 00 00 | I31: =VLOOKUP(G31,'insumos terrapl'!$C$3:$K$47,3,0) -> 2Q | J31: =VLOOKUP(G31,'insumos terrapl'!$C$3:$K$47,4,0) -> 62 | K31: =VLOOKUP(G31,'insumos terrapl'!$C$3:$K$47,5,0) -> 06 | L31: =VLOOKUP(G31,'insumos terrapl'!$C$3:$K$47,6,0) -> 02 | M31: =VLOOKUP(G31,'insumos terrapl'!$C$3:$K$47,7,0) -> 00 | N31: =VLOOKUP(G31,'insumos terrapl'!$C$3:$K$47,8,0) -> 00 | O31: =VLOOKUP(G31,'insumos terrapl'!$C$3:$K$47,9,0) -> 00
F32: P9824 | G32: Servente | H32: =VLOOKUP(G32,'insumos terrapl'!$C$3:$K$47,2,0) -> 2N 20 14 08 00 00 00 | I32: =VLOOKUP(G32,'insumos terrapl'!$C$3:$K$47,3,0) -> 2N | J32: =VLOOKUP(G32,'insumos terrapl'!$C$3:$K$47,4,0) -> 20 | K32: =VLOOKUP(G32,'insumos terrapl'!$C$3:$K$47,5,0) -> 14 | L32: =VLOOKUP(G32,'insumos terrapl'!$C$3:$K$47,6,0) -> 08 | M32: =VLOOKUP(G32,'insumos terrapl'!$C$3:$K$47,7,0) -> 00 | N32: =VLOOKUP(G32,'insumos terrapl'!$C$3:$K$47,8,0) -> 00 | O32: =VLOOKUP(G32,'insumos terrapl'!$C$3:$K$47,9,0) -> 00
A34: 2.5.1 | B34: Escavação de vala em material de 3ª categoria - com escavadeira e rompedor hidráulico | C34: 5502972 | D34: =A34 -> 2.5.1 | E34: Escavação de vala em material de 3ª categoria - resistência à compressão acima de 110 MPa - com escavadeira e rompedor hidráulico 1.700 kg | F34: 5502972
F35: E9775 | G35: Escavadeira hidráulica com martelo hidráulico de 1.700 kg - 103 kW | H35: =VLOOKUP(G35,'insumos terrapl'!$C$3:$K$47,2,0) -> 2Q 62 02 22 00 00 00 | I35: =VLOOKUP(G35,'insumos terrapl'!$C$3:$K$47,3,0) -> 2Q | J35: =VLOOKUP(G35,'insumos terrapl'!$C$3:$K$47,4,0) -> 62 | K35: =VLOOKUP(G35,'insumos terrapl'!$C$3:$K$47,5,0) -> 02 | L35: =VLOOKUP(G35,'insumos terrapl'!$C$3:$K$47,6,0) -> 22 | M35: =VLOOKUP(G35,'insumos terrapl'!$C$3:$K$47,7,0) -> 00 | N35: =VLOOKUP(G35,'insumos terrapl'!$C$3:$K$47,8,0) -> 00 | O35: =VLOOKUP(G35,'insumos terrapl'!$C$3:$K$47,9,0) -> 00
F36: M0602 | G36: Ponteiro para rompedor hidráulico de 1.700 kg | H36: =VLOOKUP(G36,'insumos terrapl'!$C$3:$K$47,2,0) -> 2Q 62 50 10 00 00 00 | I36: =VLOOKUP(G36,'insumos terrapl'!$C$3:$K$47,3,0) -> 2Q | J36: =VLOOKUP(G36,'insumos terrapl'!$C$3:$K$47,4,0) -> 62 | K36: =VLOOKUP(G36,'insumos terrapl'!$C$3:$K$47,5,0) -> 50 | L36: =VLOOKUP(G36,'insumos terrapl'!$C$3:$K$47,6,0) -> 10 | M36: =VLOOKUP(G36,'insumos terrapl'!$C$3:$K$47,7,0) -> 00 | N36: =VLOOKUP(G36,'insumos terrapl'!$C$3:$K$47,8,0) -> 00 | O36: =VLOOKUP(G36,'insumos terrapl'!$C$3:$K$47,9,0) -> 00
F37: M0602 | G37: Ponteiro para rompedor hidráulico de 1.700 kg - Caminhão carroceria 15 t | H37: =VLOOKUP(G37,'insumos terrapl'!$C$3:$K$47,2,0) -> 2Q 66 06 02 00 00 00 | I37: =VLOOKUP(G37,'insumos terrapl'!$C$3:$K$47,3,0) -> 2Q | J37: =VLOOKUP(G37,'insumos terrapl'!$C$3:$K$47,4,0) -> 66 | K37: =VLOOKUP(G37,'insumos terrapl'!$C$3:$K$47,5,0) -> 06 | L37: =VLOOKUP(G37,'insumos terrapl'!$C$3:$K$47,6,0) -> 02 | M37: =VLOOKUP(G37,'insumos terrapl'!$C$3:$K$47,7,0) -> 00 | N37: =VLOOKUP(G37,'insumos terrapl'!$C$3:$K$47,8,0) -> 00 | O37: =VLOOKUP(G37,'insumos terrapl'!$C$3:$K$47,9,0) -> 00
C39: 5502968 | D39: =A34 -> 2.5.1 | E39: Escavação de vala em material de 3ª categoria - resistência à compressão até 50 MPa - com escavadeira e rompedor hidráulico 1.700 kg | F39: 5502968
F40: E9775 | G40: Escavadeira hidráulica com martelo hidráulico de 1.700 kg - 103 kW | H40: =VLOOKUP(G40,'insumos terrapl'!$C$3:$K$47,2,0) -> 2Q 62 02 22 00 00 00 | I40: =VLOOKUP(G40,'insumos terrapl'!$C$3:$K$47,3,0) -> 2Q | J40: =VLOOKUP(G40,'insumos terrapl'!$C$3:$K$47,4,0) -> 62 | K40: =VLOOKUP(G40,'insumos terrapl'!$C$3:$K$47,5,0) -> 02 | L40: =VLOOKUP(G40,'insumos terrapl'!$C$3:$K$47,6,0) -> 22 | M40: =VLOOKUP(G40,'insumos terrapl'!$C$3:$K$47,7,0) -> 00 | N40: =VLOOKUP(G40,'insumos terrapl'!$C$3:$K$47,8,0) -> 00 | O40: =VLOOKUP(G40,'insumos terrapl'!$C$3:$K$47,9,0) -> 00
F41: M0602 | G41: Ponteiro para rompedor hidráulico de 1.700 kg | H41: =VLOOKUP(G41,'insumos terrapl'!$C$3:$K$47,2,0) -> 2Q 62 50 10 00 00 00 | I41: =VLOOKUP(G41,'insumos terrapl'!$C$3:$K$47,3,0) -> 2Q | J41: =VLOOKUP(G41,'insumos terrapl'!$C$3:$K$47,4,0) -> 62 | K41: =VLOOKUP(G41,'insumos terrapl'!$C$3:$K$47,5,0) -> 50 | L41: =VLOOKUP(G41,'insumos terrapl'!$C$3:$K$47,6,0) -> 10 | M41: =VLOOKUP(G41,'insumos terrapl'!$C$3:$K$47,7,0) -> 00 | N41: =VLOOKUP(G41,'insumos terrapl'!$C$3:$K$47,8,0) -> 00 | O41: =VLOOKUP(G41,'insumos terrapl'!$C$3:$K$47,9,0) -> 00
F42: M0602 | G42: Ponteiro para rompedor hidráulico de 1.700 kg - Caminhão carroceria 15 t | H42: =VLOOKUP(G42,'insumos terrapl'!$C$3:$K$47,2,0) -> 2Q 66 06 02 00 00 00 | I42: =VLOOKUP(G42,'insumos terrapl'!$C$3:$K$47,3,0) -> 2Q | J42: =VLOOKUP(G42,'insumos terrapl'!$C$3:$K$47,4,0) -> 66 | K42: =VLOOKUP(G42,'insumos terrapl'!$C$3:$K$47,5,0) -> 06 | L42: =VLOOKUP(G42,'insumos terrapl'!$C$3:$K$47,6,0) -> 02 | M42: =VLOOKUP(G42,'insumos terrapl'!$C$3:$K$47,7,0) -> 00 | N42: =VLOOKUP(G42,'insumos terrapl'!$C$3:$K$47,8,0) -> 00 | O42: =VLOOKUP(G42,'insumos terrapl'!$C$3:$K$47,9,0) -> 00
C44: 5502969 | D44: =A34 -> 2.5.1 | E44: Escavação de vala em material de 3ª categoria - resistência à compressão de 50 a 70 MPa - com escavadeira e rompedor hidráulico 1.700 kg | F44: 5502969
F45: E9775 | G45: Escavadeira hidráulica com martelo hidráulico de 1.700 kg - 103 kW | H45: =VLOOKUP(G45,'insumos terrapl'!$C$3:$K$47,2,0) -> 2Q 62 02 22 00 00 00 | I45: =VLOOKUP(G45,'insumos terrapl'!$C$3:$K$47,3,0) -> 2Q | J45: =VLOOKUP(G45,'insumos terrapl'!$C$3:$K$47,4,0) -> 62 | K45: =VLOOKUP(G45,'insumos terrapl'!$C$3:$K$47,5,0) -> 02 | L45: =VLOOKUP(G45,'insumos terrapl'!$C$3:$K$47,6,0) -> 22 | M45: =VLOOKUP(G45,'insumos terrapl'!$C$3:$K$47,7,0) -> 00 | N45: =VLOOKUP(G45,'insumos terrapl'!$C$3:$K$47,8,0) -> 00 | O45: =VLOOKUP(G45,'insumos terrapl'!$C$3:$K$47,9,0) -> 00
F46: M0602 | G46: Ponteiro para rompedor hidráulico de 1.700 kg | H46: =VLOOKUP(G46,'insumos terrapl'!$C$3:$K$47,2,0) -> 2Q 62 50 10 00 00 00 | I46: =VLOOKUP(G46,'insumos terrapl'!$C$3:$K$47,3,0) -> 2Q | J46: =VLOOKUP(G46,'insumos terrapl'!$C$3:$K$47,4,0) -> 62 | K46: =VLOOKUP(G46,'insumos terrapl'!$C$3:$K$47,5,0) -> 50 | L46: =VLOOKUP(G46,'insumos terrapl'!$C$3:$K$47,6,0) -> 10 | M46: =VLOOKUP(G46,'insumos terrapl'!$C$3:$K$47,7,0) -> 00 | N46: =VLOOKUP(G46,'insumos terrapl'!$C$3:$K$47,8,0) -> 00 | O46: =VLOOKUP(G46,'insumos terrapl'!$C$3:$K$47,9,0) -> 00
F47: M0602 | G47: Ponteiro para rompedor hidráulico de 1.700 kg - Caminhão carroceria 15 t | H47: =VLOOKUP(G47,'insumos terrapl'!$C$3:$K$47,2,0) -> 2Q 66 06 02 00 00 00 | I47: =VLOOKUP(G47,'insumos terrapl'!$C$3:$K$47,3,0) -> 2Q | J47: =VLOOKUP(G47,'insumos terrapl'!$C$3:$K$47,4,0) -> 66 | K47: =VLOOKUP(G47,'insumos terrapl'!$C$3:$K$47,5,0) -> 06 | L47: =VLOOKUP(G47,'insumos terrapl'!$C$3:$K$47,6,0) -> 02 | M47: =VLOOKUP(G47,'insumos terrapl'!$C$3:$K$47,7,0) -> 00 | N47: =VLOOKUP(G47,'insumos terrapl'!$C$3:$K$47,8,0) -> 00 | O47: =VLOOKUP(G47,'insumos terrapl'!$C$3:$K$47,9,0) -> 00
C49: 5502970 | D49: =A34 -> 2.5.1 | E49: Escavação de vala em material de 3ª categoria - resistência à compressão de 70 a 90 MPa - com escavadeira e rompedor hidráulico 1.700 kg | F49: 5502970
F50: E9775 | G50: Escavadeira hidráulica com martelo hidráulico de 1.700 kg - 103 kW | H50: =VLOOKUP(G50,'insumos terrapl'!$C$3:$K$47,2,0) -> 2Q 62 02 22 00 00 00 | I50: =VLOOKUP(G50,'insumos terrapl'!$C$3:$K$47,3,0) -> 2Q | J50: =VLOOKUP(G50,'insumos terrapl'!$C$3:$K$47,4,0) -> 62 | K50: =VLOOKUP(G50,'insumos terrapl'!$C$3:$K$47,5,0) -> 02 | L50: =VLOOKUP(G50,'insumos terrapl'!$C$3:$K$47,6,0) -> 22 | M50: =VLOOKUP(G50,'insumos terrapl'!$C$3:$K$47,7,0) -> 00 | N50: =VLOOKUP(G50,'insumos terrapl'!$C$3:$K$47,8,0) -> 00 | O50: =VLOOKUP(G50,'insumos terrapl'!$C$3:$K$47,9,0) -> 00
F51: M0602 | G51: Ponteiro para rompedor hidráulico de 1.700 kg | H51: =VLOOKUP(G51,'insumos terrapl'!$C$3:$K$47,2,0) -> 2Q 62 50 10 00 00 00 | I51: =VLOOKUP(G51,'insumos terrapl'!$C$3:$K$47,3,0) -> 2Q | J51: =VLOOKUP(G51,'insumos terrapl'!$C$3:$K$47,4,0) -> 62 | K51: =VLOOKUP(G51,'insumos terrapl'!$C$3:$K$47,5,0) -> 50 | L51: =VLOOKUP(G51,'insumos terrapl'!$C$3:$K$47,6,0) -> 10 | M51: =VLOOKUP(G51,'insumos terrapl'!$C$3:$K$47,7,0) -> 00 | N51: =VLOOKUP(G51,'insumos terrapl'!$C$3:$K$47,8,0) -> 00 | O51: =VLOOKUP(G51,'insumos terrapl'!$C$3:$K$47,9,0) -> 00
F52: M0602 | G52: Ponteiro para rompedor hidráulico de 1.700 kg - Caminhão carroceria 15 t | H52: =VLOOKUP(G52,'insumos terrapl'!$C$3:$K$47,2,0) -> 2Q 66 06 02 00 00 00 | I52: =VLOOKUP(G52,'insumos terrapl'!$C$3:$K$47,3,0) -> 2Q | J52: =VLOOKUP(G52,'insumos terrapl'!$C$3:$K$47,4,0) -> 66 | K52: =VLOOKUP(G52,'insumos terrapl'!$C$3:$K$47,5,0) -> 06 | L52: =VLOOKUP(G52,'insumos terrapl'!$C$3:$K$47,6,0) -> 02 | M52: =VLOOKUP(G52,'insumos terrapl'!$C$3:$K$47,7,0) -> 00 | N52: =VLOOKUP(G52,'insumos terrapl'!$C$3:$K$47,8,0) -> 00 | O52: =VLOOKUP(G52,'insumos terrapl'!$C$3:$K$47,9,0) -> 00
...

Sheet insumos terrapl
B2: Código Insumo | C2: Descrição do Insumo | D2: Classificação NBR 15965 | E2: Nível 1 | F2: Nível 2 | G2: Nível 3 | H2: Nível 4 | I2: Nível 5 | J2: Nível 6 | K2: Nível 7
B3: E9541 | C3: Trator sobre esteiras com lâmina - 259 kW | D3: =E3&" "&F3&" "&G3&" "&H3&" "&I3&" "&J3&" "&K3 -> 2Q 62 30 02 14 00 00 | E3: 2Q | F3: 62 | G3: 30 | H3: 02 | I3: 14 | J3: 00 | K3: 00
B4: P9824 | C4: Servente | D4: =E4&" "&F4&" "&G4&" "&H4&" "&I4&" "&J4&" "&K4 -> 2N 20 14 08 00 00 00 | E4: 2N | F4: 20 | G4: 14 | H4: 08 | I4: 00 | J4: 00 | K4: 00
B5: E9540 | C5: Trator sobre esteiras com lâmina - 127 kW | D5: =E5&" "&F5&" "&G5&" "&H5&" "&I5&" "&J5&" "&K5 -> 2Q 62 30 02 14 00 00 | E5: 2Q | F5: 62 | G5: 30 | H5: 02 | I5: 14 | J5: 00 | K5: 00
B6: E9524 | C6: Motoniveladora - 93 kW | D6: =E6&" "&F6&" "&G6&" "&H6&" "&I6&" "&J6&" "&K6 -> 2Q 62 30 06 02 00 00 | E6: 2Q | F6: 62 | G6: 30 | H6: 06 | I6: 02 | J6: 00 | K6: 00
B7: E9571 | C7: Caminhão tanque com capacidade de 10.000 l - 188 kW | D7: =E7&" "&F7&" "&G7&" "&H7&" "&I7&" "&J7&" "&K7 -> 2Q 66 06 26 00 00 00 | E7: 2Q | F7: 66 | G7: 06 | H7: 26 | I7: 00 | J7: 00 | K7: 00
B8: E9526 | C8: Retroescavadeira de pneus - capacidade da caçamba da pá-carregadeira de 0,76 m³ e da retroescavadeira de 0,29 m³ - 58 kW | D8: =E8&" "&F8&" "&G8&" "&H8&" "&I8&" "&J8&" "&K8 -> 2Q 62 06 02 00 00 00 | E8: 2Q | F8: 62 | G8: 06 | H8: 02 | I8: 00 | J8: 00 | K8: 00
B9: E9775 | C9: Escavadeira hidráulica com martelo hidráulico de 1.700 kg - 103 kW | D9: =E9&" "&F9&" "&G9&" "&H9&" "&I9&" "&J9&" "&K9 -> 2Q 62 02 22 00 00 00 | E9: 2Q | F9: 62 | G9: 02 | H9: 22 | I9: 00 | J9: 00 | K9: 00
B10: M0602 | C10: Ponteiro para rompedor hidráulico de 1.700 kg | D10: =E10&" "&F10&" "&G10&" "&H10&" "&I10&" "&J10&" "&K10 -> 2Q 62 50 10 00 00 00 | E10: 2Q | F10: 62 | G10: 50 | H10: 10 | I10: 00 | J10: 00 | K10: 00
B11: M0602 | C11: Ponteiro para rompedor hidráulico de 1.700 kg - Caminhão carroceria 15 t | D11: =E11&" "&F11&" "&G11&" "&H11&" "&I11&" "&J11&" "&K11 -> 2Q 66 06 02 00 00 00 | E11: 2Q | F11: 66 | G11: 06 | H11: 02 | I11: 00 | J11: 00 | K11: 00
B12: E9646 | C12: Compressor de ar portátil de 58,52 l/s (124 PCM) - 27 kW | D12: =E12&" "&F12&" "&G12&" "&H12&" "&I12&" "&J12&" "&K12 -> 2Q 42 06 18 02 02 00 | E12: 2Q | F12: 42 | G12: 06 | H12: 18 | I12: 02 | J12: 02 | K12: 00
B13: E9527 | C13: Martelete perfurador/rompedor a ar comprimido de 25 kg para rocha com capacidade de 2.040 gpm | D13: =E13&" "&F13&" "&G13&" "&H13&" "&I13&" "&J13&" "&K13 -> 2Q 42 06 02 14 02 00 | E13: 2Q | F13: 42 | G13: 06 | H13: 02 | I13: 14 | J13: 02 | K13: 00
B14: E9574 | C14: Perfuratriz sobre esteiras - 145 kW | D14: =E14&" "&F14&" "&G14&" "&H14&" "&I14&" "&J14&" "&K14 -> 2Q 58 10 10 02 06 00 | E14: 2Q | F14: 58 | G14: 10 | H14: 10 | I14: 02 | J14: 06 | K14: 00
B15: P9892 | C15: Auxiliar de blaster | D15: =E15&" "&F15&" "&G15&" "&H15&" "&I15&" "&J15&" "&K15 -> 2N 20 14 02 00 00 00 | E15: 2N | F15: 20 | G15: 14 | H15: 02 | I15: 00 | J15: 00 | K15: 00
B16: P9852 | C16: Blaster | D16: =E16&" "&F16&" "&G16&" "&H16&" "&I16&" "&J16&" "&K16 -> 2N 20 14 02 00 00 00 | E16: 2N | F16: 20 | G16: 14 | H16: 02 | I16: 00 | J16: 00 | K16: 00
B17: M2062 | C17: Coroa de botões esféricos linha T38 - D = 64 mm (2 1/2") | D17: =E17&" "&F17&" "&G17&" "&H17&" "&I17&" "&J17&" "&K17 -> 2N 58 06 00 00 00 00 | E17: 2N | F17: 58 | G17: 06 | H17: 00 | I17: 00 | J17: 00 | K17: 00
B18: M2042 | C18: Emulsão explosiva encartuchada | D18: =E18&" "&F18&" "&G18&" "&H18&" "&I18&" "&J18&" "&K18 -> 2Q 58 06 02 28 00 00 | E18: 2Q | F18: 58 | G18: 06 | H18: 02 | I18: 28 | J18: 00 | K18: 00
B19: M2065 | C19: Haste linha T38 para perfuratriz sobre esteiras - D = 38,0 mm (1 1/2") e C = 3,05 m | D19: =E19&" "&F19&" "&G19&" "&H19&" "&I19&" "&J19&" "&K19 -> 2N 58 06 00 00 00 00 | E19: 2N | F19: 58 | G19: 06 | H19: 00 | I19: 00 | J19: 00 | K19: 00
B20: M2066 | C20: Luva em aço linha T38 para perfuratriz sobre esteiras - D = 38,0 mm (1 1/2") | D20: =E20&" "&F20&" "&G20&" "&H20&" "&I20&" "&J20&" "&K20 -> 2N 58 06 00 00 00 00 | E20: 2N | F20: 58 | G20: 06 | H20: 00 | I20: 00 | J20: 00 | K20: 00
B21: M2144 | C21: Nonel de coluna - C = 6,0 m | D21: =E21&" "&F21&" "&G21&" "&H21&" "&I21&" "&J21&" "&K21 -> 2N 58 06 00 00 00 00 | E21: 2N | F21: 58 | G21: 06 | H21: 00 | I21: 00 | J21: 00 | K21: 00
B22: M2144 | C22: Nonel de coluna - C = 6,0 m | D22: =E22&" "&F22&" "&G22&" "&H22&" "&I22&" "&J22&" "&K22 -> 2N 58 06 00 00 00 00 | E22: 2N | F22: 58 | G22: 06 | H22: 00 | I22: 00 | J22: 00 | K22: 00
B23: M2143 | C23: Nonel de ligação - C = 6,0 m | D23: =E23&" "&F23&" "&G23&" "&H23&" "&I23&" "&J23&" "&K23 -> 2N 58 06 00 00 00 00 | E23: 2N | F23: 58 | G23: 06 | H23: 00 | I23: 00 | J23: 00 | K23: 00
B24: M2146 | C24: Nonel iniciador - C = 150,0 m | D24: =E24&" "&F24&" "&G24&" "&H24&" "&I24&" "&J24&" "&K24 -> 2N 58 06 00 00 00 00 | E24: 2N | F24: 58 | G24: 06 | H24: 00 | I24: 00 | J24: 00 | K24: 00
... B26: M2145 | C26: Série de brocas integrais S12 | D26: =E26&" "&F26&" "&G26&" "&H26&" "&I26&" "&J26&" "&K26 -> 2N 58 06 00 00 00 00 | E26: 2N | F26: 58 | G26: 06 | H26: 00 | I26: 00 | J26: 00 | K26: 00
B27: E9671 | C27: Compressor de ar portátil de 363,87 l/s (771 PCM) - 158,13 kW | D27: =E27&" "&F27&" "&G27&" "&H27&" "&I27&" "&J27&" "&K27 -> 2Q 42 06 18 02 02 00 | E27: 2Q | F27: 42 | G27: 06 | H27: 18 | I27: 02 | J27: 02 | K27: 00
B28: M0421 | C28: Argamassa expansiva para desmonte de rocha e demolição de concreto | D28: =E28&" "&F28&" "&G28&" "&H28&" "&I28&" "&J28&" "&K28 -> 2C 4 02 14 00 00 00 | E28: 2C | F28: 4 | G28: 02 | H28: 14 | I28: 00 | J28: 00 | K28: 00
B29: M0421 | C29: Argamassa expansiva para desmonte de rocha e demolição de concreto - Caminhão carroceria 15 t | D29: =E29&" "&F29&" "&G29&" "&H29&" "&I29&" "&J29&" "&K29 -> 2Q 66 06 02 00 00 00 | E29: 2Q | F29: 66 | G29: 06 | H29: 02 | I29: 00 | J29: 00 | K29: 00
B30: M1391 | C30: Ponteiro para martelete - D = 22 mm e C = 1,00 m | D30: =E30&" "&F30&" "&G30&" "&H30&" "&I30&" "&J30&" "&K30 -> 2Q 62 50 10 00 00 00 | E30: 2Q | F30: 62 | G30: 50 | H30: 10 | I30: 00 | J30: 00 | K30: 00
B31: E9523 | C31: Motoscraper - 304 kW | D31: =E31&" "&F31&" "&G31&" "&H31&" "&I31&" "&J31&" "&K31 -> 2Q 62 26 00 00 00 00 | E31: 2Q | F31: 62 | G31: 26 | H31: 00 | I31: 00 | J31: 00 | K31: 00
B32: E9667 | C32: Caminhão basculante com capacidade de 14 m³ - 210 kW | D32: =E32&" "&F32&" "&G32&" "&H32&" "&I32&" "&J32&" "&K32 -> 2Q 66 10 02 00 00 00 | E32: 2Q | F32: 66 | G32: 10 | H32: 02 | I32: 00 | J32: 00 | K32: 00
B33: E9511 | C33: Carregadeira de pneus com capacidade de 3,40 m³ - 195 kW | D33: =E33&" "&F33&" "&G33&" "&H33&" "&I33&" "&J33&" "&K33 -> 2Q 62 10 06 00 00 00 | E33: 2Q | F33: 62 | G33: 10 | H33: 06 | I33: 00 | J33: 00 | K33: 00
B34: E9667 | C34: Caminhão basculante com capacidade de 14 m³ - 210 kW | D34: =E34&" "&F34&" "&G34&" "&H34&" "&I34&" "&J34&" "&K34 -> 2Q 62 10 06 00 00 00 | E34: 2Q | F34: 62 | G34: 10 | H34: 06 | I34: 00 | J34: 00 | K34: 00
B35: E9565 | C35: Trator sobre esteiras com lâmina e escarificador - 259 kW | D35: =E35&" "&F35&" "&G35&" "&H35&" "&I35&" "&J35&" "&K35 -> 2Q 62 30 02 10 00 00 | E35: 2Q | F35: 62 | G35: 30 | H35: 02 | I35: 10 | J35: 00 | K35: 00
B36: E9515 | C36: Escavadeira hidráulica sobre esteiras com caçamba com capacidade de 1,56 m³ - 118 kW | D36: =E36&" "&F36&" "&G36&" "&H36&" "&I36&" "&J36&" "&K36 -> 2Q 62 02 10 00 00 00 | E36: 2Q | F36: 62 | G36: 02 | H36: 10 | I36: 00 | J36: 00 | K36: 00
B37: E9672 | C37: Caminhão basculante para rocha com capacidade de 12 m³ - 188 kW | D37: =E37&" "&F37&" "&G37&" "&H37&" "&I37&" "&J37&" "&K37 -> 2Q 66 10 02 00 00 00 | E37: 2Q | F37: 66 | G37: 10 | H37: 02 | I37: 00 | J37: 00 | K37: 00
B38: E9117 | C38: Carregadeira de pneus para rocha com capacidade de 2,50 m³ - 105 kW | D38: =E38&" "&F38&" "&G38&" "&H38&" "&I38&" "&J38&" "&K38 -> 2Q 62 10 06 00 00 00 | E38: 2Q | F38: 62 | G38: 10 | H38: 06 | I38: 00 | J38: 00 | K38: 00
B39: E9540 | C39: Trator sobre esteiras com lâmina - 127 kW | D39: =E39&" "&F39&" "&G39&" "&H39&" "&I39&" "&J39&" "&K39 -> 2Q 62 30 02 06 00 00 | E39: 2Q | F39: 62 | G39: 30 | H39: 02 | I39: 06 | J39: 00 | K39: 00
B40: E9576 | C40: Escavadeira hidráulica de longo alcance sobre esteiras - 103 kW | D40: =E40&" "&F40&" "&G40&" "&H40&" "&I40&" "&J40&" "&K40 -> 2Q 62 02 18 00 00 00 | E40: 2Q | F40: 62 | G40: 02 | H40: 18 | I40: 00 | J40: 00 | K40: 00
... B47: M0081 | C47: Areia grossa - Caminhão basculante 10 m³ | D47: =E47&" "&F47&" "&G47&" "&H47&" "&I47&" "&J47&" "&K47 -> 2Q 66 10 02 00 00 00 | E47: 2Q | F47: 66 | G47: 10 | H47: 02 | I47: 00 | J47: 00 | K47: 00

Sheet DATASET_NLP
B3: Código da Composição | C3: Descrição SICRO | D3: 3. SUBGRUPO_G55 | E3: Codigo do Insumo | F3: Descrição do Insumo | G3: Classificação NBR 15965 | H3: 7. Nível 1 | I3: 8. Nível 2 | J3: 9. Nível 3 | K3: 10. Nível 4 | L3: 11. Nível 5 | M3: 12. Nível 6 | N3: 13. Nível 7 | O3: TEXTO_SERVICO
B4: 5501700 | C4: Desmatamento, destocamento e limpeza-área com árvores de diâmetro até 0, 15 m | D4: =VLOOKUP(B4,CORRESPONDENCIA!$C$4:$F$2105,2,0) -> 2.1.1 | E4: =CORRESPONDENCIA!F6 -> E9541 | F4: Trator sobre esteiras com lâmina - 259 kW | G4: ='insumos terrapl'!D3 -> 2Q 62 30 02 14 00 00 | H4: ='insumos terrapl'!E3 -> 2Q | I4: ='insumos terrapl'!F3 -> 62 | J4: ='insumos terrapl'!G3 -> 30 | K4: ='insumos terrapl'!H3 -> 02 | L4: ='insumos terrapl'!I3 -> 14 | M4: ='insumos terrapl'!J3 -> 00 | N4: ='insumos terrapl'!K3 -> 00 | O4: =C4 & " | Insumo principal: " & F4 -> Desmatamento, destocamento e limpeza-área com árvores de diâmetro até 0, 15 m | Insumo principal: Trator sobre esteiras com lâmina - 259 kW
B5: 5501701 | C5: Destocamento de árvores de diâmetro de 0,15 a 0,30 m | D5: =VLOOKUP(B5,CORRESPONDENCIA!$C$4:$F$2105,2,0) -> 2.1.2 | E5: =CORRESPONDENCIA!F10 -> E9541 | F5: Trator sobre esteiras com lâmina - 259 kW | G5: ='insumos terrapl'!D3 -> 2Q 62 30 02 14 00 00 | H5: ='insumos terrapl'!E3 -> 2Q | I5: ='insumos terrapl'!F3 -> 62 | J5: ='insumos terrapl'!G3 -> 30 | K5: ='insumos terrapl'!H3 -> 02 | L5: ='insumos terrapl'!I3 -> 14 | M5: ='insumos terrapl'!J3 -> 00 | N5: ='insumos terrapl'!K3 -> 00 | O5: =C5 & " | Insumo principal: " & F5 -> Destocamento de árvores de diâmetro de 0,15 a 0,30 m | Insumo principal: Trator sobre esteiras com lâmina - 259 kW
B6: 5501702 | C6: Destocamento de árvores de diâmetro superior a 0, 30 m | D6: =VLOOKUP(B6,CORRESPONDENCIA!$C$4:$F$2105,2,0) -> 2.1.2 | E6: =CORRESPONDENCIA!F14 -> E9541 | F6: Trator sobre esteiras com lâmina - 259 kW | G6: ='insumos terrapl'!D3 -> 2Q 62 30 02 14 00 00 | H6: ='insumos terrapl'!E3 -> 2Q | I6: ='insumos terrapl'!F3 -> 62 | J6: ='insumos terrapl'!G3 -> 30 | K6: ='insumos terrapl'!H3 -> 02 | L6: ='insumos terrapl'!I3 -> 14 | M6: ='insumos terrapl'!J3 -> 00 | N6: ='insumos terrapl'!K3 -> 00 | O6: =C6 & " | Insumo principal: " & F6 -> Destocamento de árvores de diâmetro superior a 0, 30 m | Insumo principal: Trator sobre esteiras com lâmina - 259 kW
B7: 5502985 | C7: Limpeza mecanizada da camada vegetal | D7: =VLOOKUP(B7,CORRESPONDENCIA!$C$4:$F$2105,2,0) -> 2.1.3 | E7: =CORRESPONDENCIA!F18 -> E9540 | F7: Trator sobre esteiras com lâmina - 127 kW | G7: ='insumos terrapl'!D5 -> 2Q 62 30 02 14 00 00 | H7: ='insumos terrapl'!E5 -> 2Q | I7: ='insumos terrapl'!F5 -> 62 | J7: ='insumos terrapl'!G5 -> 30 | K7: ='insumos terrapl'!H5 -> 02 | L7: ='insumos terrapl'!I5 -> 14 | M7: ='insumos terrapl'!J5 -> 00 | N7: ='insumos terrapl'!K5 -> 00 | O7: =C7 & " | Insumo principal: " & F7 -> Limpeza mecanizada da camada vegetal | Insumo principal: Trator sobre esteiras com lâmina - 127 kW
B8: 5502986 | C8: Expurgo de jazida | D8: =VLOOKUP(B8,CORRESPONDENCIA!$C$4:$F$2105,2,0) -> 2.2.1 | E8: =CORRESPONDENCIA!F21 -> E9540 | F8: Trator sobre esteiras com lâmina - 127 kW | G8: ='insumos terrapl'!D5 -> 2Q 62 30 02 14 00 00 | H8: ='insumos terrapl'!E5 -> 2Q | I8: ='insumos terrapl'!F5 -> 62 | J8: ='insumos terrapl'!G5 -> 30 | K8: ='insumos terrapl'!H5 -> 02 | L8: ='insumos terrapl'!I5 -> 14 | M8: ='insumos terrapl'!J5 -> 00 | N8: ='insumos terrapl'!K5 -> 00 | O8: =C8 & " | Insumo principal: " & F8 -> Expurgo de jazida | Insumo principal: Trator sobre esteiras com lâmina - 127 kW
B9: 5503018 | C9: Manutenção de caminhos de serviço | D9: =VLOOKUP(B9,CORRESPONDENCIA!$C$4:$F$2105,2,0) -> 2.3.1 | E9: =CORRESPONDENCIA!F25 -> E9524 | F9: Motoniveladora - 93 kW | G9: ='insumos terrapl'!D6 -> 2Q 62 30 06 02 00 00 | H9: ='insumos terrapl'!E6 -> 2Q | I9: ='insumos terrapl'!F6 -> 62 | J9: ='insumos terrapl'!G6 -> 30 | K9: ='insumos terrapl'!H6 -> 06 | L9: ='insumos terrapl'!I6 -> 02 | M9: ='insumos terrapl'!J6 -> 00 | N9: ='insumos terrapl'!K6 -> 00 | O9: =C9 & " | Insumo principal: " & F9 -> Manutenção de caminhos de serviço | Insumo principal: Motoniveladora - 93 kW
B10: 5503020 | C10: Umedecimento de caminho de serviço | D10: =VLOOKUP(B10,CORRESPONDENCIA!$C$4:$F$2105,2,0) -> 2.3.2 | E10: =CORRESPONDENCIA!F211 -> E9667 | F10: Caminhão tanque com capacidade de 10.000 l - 188 kW | G10: ='insumos terrapl'!D7 -> 2Q 66 06 26 00 00 00 | H10: ='insumos terrapl'!E7 -> 2Q | I10: ='insumos terrapl'!F7 -> 66 | J10: ='insumos terrapl'!G7 -> 06 | K10: ='insumos terrapl'!H7 -> 26 | L10: ='insumos terrapl'!I7 -> 00 | M10: ='insumos terrapl'!J7 -> 00 | N10: ='insumos terrapl'!K7 -> 00 | O10: =C10 & " | Insumo principal: " & F10 -> Umedecimento de caminho de serviço | Insumo principal: Caminhão tanque com capacidade de 10.000 l - 188 kW
B11: 5501706 | C11: Escavação mecânica com retroescavadeira em material de 1ª categoria | D11: =VLOOKUP(B11,CORRESPONDENCIA!$C$4:$F$2105,2,0) -> 2.4.1 | E11: =CORRESPONDENCIA!F31 -> E9526 | F11: Retroescavadeira de pneus - capacidade da caçamba da pá-carregadeira de 0,76 m³ e da retroescavadeira de 0,29 m³ - 58 kW | G11: ='insumos terrapl'!D8 -> 2Q 62 06 02 00 00 00 | H11: ='insumos terrapl'!E8 -> 2Q | I11: ='insumos terrapl'!F8 -> 62 | J11: ='insumos terrapl'!G8 -> 06 | K11: ='insumos terrapl'!H8 -> 02 | L11: ='insumos terrapl'!I8 -> 00 | M11: ='insumos terrapl'!J8 -> 00 | N11: ='insumos terrapl'!K8 -> 00 | O11: =C11 & " | Insumo principal: " & F11 -> Escavação mecânica com retroescavadeira em material de 1ª categoria | Insumo principal: Retroescavadeira de pneus - capacidade da caçamba da pá-carregadeira de 0,76 m³ e da retroescavadeira de 0,29 m³ - 58 kW
B12: 5502972 | C12: Escavação de vala em material de 3ª categoria - resistência à compressão acima de 110 MPa - com escavadeira e rompedor hidráulico 1.700 kg | D12: =VLOOKUP(B12,CORRESPONDENCIA!$C$4:$F$2105,2,0) -> 2.5.1 | E12: M0602 | F12: Ponteiro para rompedor hidráulico de 1.700 kg | G12: ='insumos terrapl'!D10 -> 2Q 62 50 10 00 00 00 | H12: ='insumos terrapl'!E10 -> 2Q | I12: ='insumos terrapl'!F10 -> 62 | J12: ='insumos terrapl'!G10 -> 50 | K12: ='insumos terrapl'!H10 -> 10 | L12: ='insumos terrapl'!I10 -> 00 | M12: ='insumos terrapl'!J10 -> 00 | N12: ='insumos terrapl'!K10 -> 00 | O12: =C12 & " | Insumo principal: " & F12 -> Escavação de vala em material de 3ª categoria - resistência à compressão acima de 110 MPa - com escavadeira e rompedor hidráulico 1.700 kg | Insumo principal: Ponteiro para rompedor hidráulico de 1.700 kg
B13: 5502968 | C13: Escavação de vala em material de 3ª categoria - resistência à compressão até 50 MPa - com escavadeira e rompedor hidráulico 1.700 kg | D13: =VLOOKUP(B13,CORRESPONDENCIA!$C$4:$F$2105,2,0) -> 2.5.1 | E13: M0602 | F13: Ponteiro para rompedor hidráulico de 1.700 kg | G13: ='insumos terrapl'!D10 -> 2Q 62 50 10 00 00 00 | H13: ='insumos terrapl'!E10 -> 2Q | I13: ='insumos terrapl'!F10 -> 62 | J13: ='insumos terrapl'!G10 -> 50 | K13: ='insumos terrapl'!H10 -> 10 | L13: ='insumos terrapl'!I10 -> 00 | M13: ='insumos terrapl'!J10 -> 00 | N13: ='insumos terrapl'!K10 -> 00 | O13: =C13 & " | Insumo principal: " & F13 -> Escavação de vala em material de 3ª categoria - resistência à compressão até 50 MPa - com escavadeira e rompedor hidráulico 1.700 kg | Insumo principal: Ponteiro para rompedor hidráulico de 1.700 kg
B14: 5502969 | C14: Escavação de vala em material de 3ª categoria - resistência à compressão de 50 a 70 MPa - com escavadeira e rompedor hidráulico 1.700 kg | D14: =VLOOKUP(B14,CORRESPONDENCIA!$C$4:$F$2105,2,0) -> 2.5.1 | E14: M0602 | F14: Ponteiro para rompedor hidráulico de 1.700 kg | G14: ='insumos terrapl'!D10 -> 2Q 62 50 10 00 00 00 | H14: ='insumos terrapl'!E10 -> 2Q | I14: ='insumos terrapl'!F10 -> 62 | J14: ='insumos terrapl'!G10 -> 50 | K14: ='insumos terrapl'!H10 -> 10 | L14: ='insumos terrapl'!I10 -> 00 | M14: ='insumos terrapl'!J10 -> 00 | N14: ='insumos terrapl'!K10 -> 00 | O14: =C14 & " | Insumo principal: " & F14 -> Escavação de vala em material de 3ª categoria - resistência à compressão de 50 a 70 MPa - com escavadeira e rompedor hidráulico 1.700 kg | Insumo principal: Ponteiro para rompedor hidráulico de 1.700 kg
B15: 5502970 | C15: Escavação de vala em material de 3ª categoria - resistência à compressão de 70 a 90 MPa - com escavadeira e rompedor hidráulico 1.700 kg | D15: =VLOOKUP(B15,CORRESPONDENCIA!$C$4:$F$2105,2,0) -> 2.5.1 | E15: M0602 | F15: Ponteiro para rompedor hidráulico de 1.700 kg | G15: ='insumos terrapl'!D10 -> 2Q 62 50 10 00 00 00 | H15: ='insumos terrapl'!E10 -> 2Q | I15: ='insumos terrapl'!F10 -> 62 | J15: ='insumos terrapl'!G10 -> 50 | K15: ='insumos terrapl'!H10 -> 10 | L15: ='insumos terrapl'!I10 -> 00 | M15: ='insumos terrapl'!J10 -> 00 | N15: ='insumos terrapl'!K10 -> 00 | O15: =C15 & " | Insumo principal: " & F15 -> Escavação de vala em material de 3ª categoria - resistência à compressão de 70 a 90 MPa - com escavadeira e rompedor hidráulico 1.700 kg | Insumo principal: Ponteiro para rompedor hidráulico de 1.700 kg
B16: 5502971 | C16: Escavação de vala em material de 3ª categoria - resistência à compressão de 90 a 110 MPa - com escavadeira e rompedor hidráulico 1.700 kg | D16: =VLOOKUP(B16,CORRESPONDENCIA!$C$4:$F$2105,2,0) -> 2.5.1 | E16: =CORRESPONDENCIA!F56 -> M0602 | F16: Ponteiro para rompedor hidráulico de 1.700 kg | G16: ='insumos terrapl'!D10 -> 2Q 62 50 10 00 00 00 | H16: ='insumos terrapl'!E10 -> 2Q | I16: ='insumos terrapl'!F10 -> 62 | J16: ='insumos terrapl'!G10 -> 50 | K16: ='insumos terrapl'!H10 -> 10 | L16: ='insumos terrapl'!I10 -> 00 | M16: ='insumos terrapl'!J10 -> 00 | N16: ='insumos terrapl'!K10 -> 00 | O16: =C16 & " | Insumo principal: " & F16 -> Escavação de vala em material de 3ª categoria - resistência à compressão de 90 a 110 MPa - com escavadeira e rompedor hidráulico 1.700 kg | Insumo principal: Ponteiro para rompedor hidráulico de 1.700 kg
B17: 5502967 | C17: Escavação em material de 3ª categoria - resistência à compressão acima de 110 MPa - com escavadeira e rompedor hidráulico 1.700 kg | D17: =VLOOKUP(B17,CORRESPONDENCIA!$C$4:$F$2105,2,0) -> 2.5.2 | E17: M0602 | F17: Ponteiro para rompedor hidráulico de 1.700 kg | G17: ='insumos terrapl'!D10 -> 2Q 62 50 10 00 00 00 | H17: ='insumos terrapl'!E10 -> 2Q | I17: ='insumos terrapl'!F10 -> 62 | J17: ='insumos terrapl'!G10 -> 50 | K17: ='insumos terrapl'!H10 -> 10 | L17: ='insumos terrapl'!I10 -> 00 | M17: ='insumos terrapl'!J10 -> 00 | N17: ='insumos terrapl'!K10 -> 00 | O17: =C17 & " | Insumo principal: " & F17 -> Escavação em material de 3ª categoria - resistência à compressão acima de 110 MPa - com escavadeira e rompedor hidráulico 1.700 kg | Insumo principal: Ponteiro para rompedor hidráulico de 1.700 kg
B18: 5502963 | C18: Escavação em material de 3ª categoria - resistência à compressão até 50 MPa - com escavadeira e rompedor hidráulico 1.700 kg | D18: =VLOOKUP(B18,CORRESPONDENCIA!$C$4:$F$2105,2,0) -> 2.5.2 | E18: M0602 | F18: Ponteiro para rompedor hidráulico de 1.700 kg | G18: ='insumos terrapl'!D10 -> 2Q 62 50 10 00 00 00 | H18: ='insumos terrapl'!E10 -> 2Q | I18: ='insumos terrapl'!F10 -> 62 | J18: ='insumos terrapl'!G10 -> 50 | K18: ='insumos terrapl'!H10 -> 10 | L18: ='insumos terrapl'!I10 -> 00 | M18: ='insumos terrapl'!J10 -> 00 | N18: ='insumos terrapl'!K10 -> 00 | O18: =C18 & " | Insumo principal: " & F18 -> Escavação em material de 3ª categoria - resistência à compressão até 50 MPa - com escavadeira e rompedor hidráulico 1.700 kg | Insumo principal: Ponteiro para rompedor hidráulico de 1.700 kg
B19: 5502964 | C19: Escavação em material de 3ª categoria - resistência à compressão de 50 a 70 MPa - com escavadeira e rompedor hidráulico 1.700 kg | D19: =VLOOKUP(B19,CORRESPONDENCIA!$C$4:$F$2105,2,0) -> 2.5.2 | E19: M0602 | F19: Ponteiro para rompedor hidráulico de 1.700 kg | G19: ='insumos terrapl'!D10 -> 2Q 62 50 10 00 00 00 | H19: ='insumos terrapl'!E10 -> 2Q | I19: ='insumos terrapl'!F10 -> 62 | J19: ='insumos terrapl'!G10 -> 50 | K19: ='insumos terrapl'!H10 -> 10 | L19: ='insumos terrapl'!I10 -> 00 | M19: ='insumos terrapl'!J10 -> 00 | N19: ='insumos terrapl'!K10 -> 00 | O19: =C19 & " | Insumo principal: " & F19 -> Escavação em material de 3ª categoria - resistência à compressão de 50 a 70 MPa - com escavadeira e rompedor hidráulico 1.700 kg | Insumo principal: Ponteiro para rompedor hidráulico de 1.700 kg
B20: 5502965 | C20: Escavação em material de 3ª categoria - resistência à compressão de 70 a 90 MPa - com escavadeira e rompedor hidráulico 1.700 kg | D20: =VLOOKUP(B20,CORRESPONDENCIA!$C$4:$F$2105,2,0) -> 2.5.2 | E20: M0602 | F20: Ponteiro para rompedor hidráulico de 1.700 kg | G20: ='insumos terrapl'!D10 -> 2Q 62 50 10 00 00 00 | H20: ='insumos terrapl'!E10 -> 2Q | I20: ='insumos terrapl'!F10 -> 62 | J20: ='insumos terrapl'!G10 -> 50 | K20: ='insumos terrapl'!H10 -> 10 | L20: ='insumos terrapl'!I10 -> 00 | M20: ='insumos terrapl'!J10 -> 00 | N20: ='insumos terrapl'!K10 -> 00 | O20: =C20 & " | Insumo principal: " & F20 -> Escavação em material de 3ª categoria - resistência à compressão de 70 a 90 MPa - com escavadeira e rompedor hidráulico 1.700 kg | Insumo principal: Ponteiro para rompedor hidráulico de 1.700 kg
B21: 5502966 | C21: Escavação em material de 3ª categoria - resistência à compressão de 90 a 110 MPa - com escavadeira e rompedor hidráulico 1.700 kg | D21: =VLOOKUP(B21,CORRESPONDENCIA!$C$4:$F$2105,2,0) -> 2.5.2 | E21: =CORRESPONDENCIA!F108 -> E9527 | F21: Martelete perfurador/rompedor a ar comprimido de 25 kg para rocha com capacidade de 2.040 gpm | G21: ='insumos terrapl'!D13 -> 2Q 42 06 02 14 02 00 | H21: ='insumos terrapl'!E13 -> 2Q | I21: ='insumos terrapl'!F13 -> 42 | J21: ='insumos terrapl'!G13 -> 06 | K21: ='insumos terrapl'!H13 -> 02 | L21: ='insumos terrapl'!I13 -> 14 | M21: ='insumos terrapl'!J13 -> 02 | N21: ='insumos terrapl'!K13 -> 00 | O21: =C21 & " | Insumo principal: " & F21 -> Escavação em material de 3ª categoria - resistência à compressão de 90 a 110 MPa - com escavadeira e rompedor hidráulico 1.700 kg | Insumo principal: Martelete perfurador/rompedor a ar comprimido de 25 kg para rocha com capacidade de 2.040 gpm
B22: 5502977 | C22: Fragmentação de blocos de rocha com escavadeira e rompedor hidráulico | D22: =VLOOKUP(B22,CORRESPONDENCIA!$C$4:$F$2105,2,0) -> 2.5.3 | E22: E9775 | F22: Escavadeira hidráulica com martelo hidráulico de 1.700 kg - 103 kW | G22: ='insumos terrapl'!D14 -> 2Q 58 10 10 02 06 00 | H22: ='insumos terrapl'!#REF! -> #REF! | I22: ='insumos terrapl'!#REF! -> #REF! | J22: ='insumos terrapl'!#REF! -> #REF! | K22: ='insumos terrapl'!#REF! -> #REF! | L22: ='insumos terrapl'!#REF! -> #REF! | M22: ='insumos terrapl'!#REF! -> #REF! | N22: ='insumos terrapl'!#REF! -> #REF! | O22: =C22 & " | Insumo principal: " & F22 -> Fragmentação de blocos de rocha com escavadeira e rompedor hidráulico | Insumo principal: Escavadeira hidráulica com martelo hidráulico de 1.700 kg - 103 kW
B23: 5502993 | C23: Escavação em material de 3ª categoria - com perfuratriz sobre esteiras | D23: =VLOOKUP(B23,CORRESPONDENCIA!$C$4:$F$2105,2,0) -> 2.5.4 | E23: E9574 | F23: Perfuratriz sobre esteiras - 145 kW | G23: ='insumos terrapl'!D14 -> 2Q 58 10 10 02 06 00 | H23: ='insumos terrapl'!E14 -> 2Q | I23: ='insumos terrapl'!F14 -> 58 | J23: ='insumos terrapl'!G14 -> 10 | K23: ='insumos terrapl'!H14 -> 10 | L23: ='insumos terrapl'!I14 -> 02 | M23: ='insumos terrapl'!J14 -> 06 | N23: ='insumos terrapl'!K14 -> 00 | O23: =C23 & " | Insumo principal: " & F23 -> Escavação em material de 3ª categoria - com perfuratriz sobre esteiras | Insumo principal: Perfuratriz sobre esteiras - 145 kW
B24: 5505766 | C24: Desmonte de material de 3ªcategoria a frio - com argamassa expansiva a céu aberto | D24: =VLOOKUP(B24,CORRESPONDENCIA!$C$4:$F$2105,2,0) -> #N/A | E24: E9671 | F24: Compressor de ar portátil de 363,87 l/s (771 PCM) - 158,13 kW | G24: ='insumos terrapl'!D27 -> 2Q 42 06 18 02 02 00 | H24: ='insumos terrapl'!E27 -> 2Q | I24: ='insumos terrapl'!F27 -> 42 | J24: ='insumos terrapl'!G27 -> 06 | K24: ='insumos terrapl'!H27 -> 18 | L24: ='insumos terrapl'!I27 -> 02 | M24: ='insumos terrapl'!J27 -> 02 | N24: ='insumos terrapl'!K27 -> 00 | O24: =C24 & " | Insumo principal: " & F24 -> Desmonte de material de 3ªcategoria a frio - com argamassa expansiva a céu aberto | Insumo principal: Compressor de ar portátil de 363,87 l/s (771 PCM) - 158,13 kW
B25: 5515739 | C25: Desmonte de matacões ou bloco de rocha por meio de explosivos | D25: =VLOOKUP(B25,CORRESPONDENCIA!$C$4:$F$2105,2,0) -> 2.5.6 | E25: E9646 | F25: Compressor de ar portátil de 58,52 l/s (124 PCM) - 27 kW | G25: ='insumos terrapl'!D12 -> 2Q 42 06 18 02 02 00 | H25: ='insumos terrapl'!E12 -> 2Q | I25: ='insumos terrapl'!F12 -> 42 | J25: ='insumos terrapl'!G12 -> 06 | K25: ='insumos terrapl'!H12 -> 18 | L25: ='insumos terrapl'!I12 -> 02 | M25: ='insumos terrapl'!J12 -> 02 | N25: ='insumos terrapl'!K12 -> 00 | O25: =C25 & " | Insumo principal: " & F25 -> Desmonte de matacões ou bloco de rocha por meio de explosivos | Insumo principal: Compressor de ar portátil de 58,52 l/s (124 PCM) - 27 kW
B26: 5505768 | C26: Pré-fissuramento de material de 3ª categoria | D26: =VLOOKUP(B26,CORRESPONDENCIA!$C$4:$F$2105,2,0) -> 2.5.7 | E26: E9574 | F26: Perfuratriz sobre esteiras - 145 kW | G26: =G23 -> 2Q 58 10 10 02 06 00 | H26: =H23 -> 2Q | I26: =I23 -> 58 | J26: =J23 -> 10 | K26: =K23 -> 10 | L26: =L23 -> 02 | M26: =M23 -> 06 | N26: =N23 -> 00 | O26: =C26 & " | Insumo principal: " & F26 -> Pré-fissuramento de material de 3ª categoria | Insumo principal: Perfuratriz sobre esteiras - 145 kW
B27: 5500991 | C27: Desmonte de blocos de rocha com martelete pneumático | D27: =VLOOKUP(B27,CORRESPONDENCIA!$C$4:$F$2105,2,0) -> 2.5.8 | E27: E9646 | F27: Compressor de ar portátil de 58,52 l/s (124 PCM) - 27 kW | G27: =G25 -> 2Q 42 06 18 02 02 00 | H27: =H25 -> 2Q | I27: =I25 -> 42 | J27: =J25 -> 06 | K27: =K25 -> 18 | L27: =L25 -> 02 | M27: =M25 -> 02 | N27: =N25 -> 00 | O27: =C27 & " | Insumo principal: " & F27 -> Desmonte de blocos de rocha com martelete pneumático | Insumo principal: Compressor de ar portátil de 58,52 l/s (124 PCM) - 27 kW
B28: 5501716 | C28: Escavação, carga e transporte em material de 1ª categoria - DMT de 1.000 a 1.200 m com motoscraper | D28: =VLOOKUP(B28,CORRESPONDENCIA!$C$4:$F$2105,2,0) -> 2.6.1 | E28: E9523 | F28: Motoscraper - 304 kW | G28: ='insumos terrapl'!D31 -> 2Q 62 26 00 00 00 00 | H28: ='insumos terrapl'!E31 -> 2Q | I28: ='insumos terrapl'!F31 -> 62 | J28: ='insumos terrapl'!G31 -> 26 | K28: ='insumos terrapl'!H31 -> 00 | L28: ='insumos terrapl'!I31 -> 00 | M28: ='insumos terrapl'!J31 -> 00 | N28: ='insumos terrapl'!K31 -> 00 | O28: =C28 & " | Insumo principal: " & F28 -> Escavação, carga e transporte em material de 1ª categoria - DMT de 1.000 a 1.200 m com motoscraper | Insumo principal: Motoscraper - 304 kW
B29: 5501717 | C29: Escavação, carga e transporte em material de 1ª categoria - DMT de 1.200 a 1.400 m com motoscraper | D29: =VLOOKUP(B29,CORRESPONDENCIA!$C$4:$F$2105,2,0) -> 2.6.1 | E29: E9523 | F29: Motoscraper - 304 kW | G29: =G28 -> 2Q 62 26 00 00 00 00 | H29: =H28 -> 2Q | I29: =I28 -> 62 | J29: =J28 -> 26 | K29: =K28 -> 00 | L29: =L28 -> 00 | M29: =M28 -> 00 | N29: =N28 -> 00 | O29: =C29 & " | Insumo principal: " & F29 -> Escavação, carga e transporte em material de 1ª categoria - DMT de 1.200 a 1.400 m com motoscraper | Insumo principal: Motoscraper - 304 kW
B30: 5501712 | C30: Escavação, carga e transporte em material de 1ª categoria - DMT de 200 a 400 m com motoscraper | D30: =VLOOKUP(B30,CORRESPONDENCIA!$C$4:$F$2105,2,0) -> 2.6.1 | E30: E9523 | F30: Motoscraper - 304 kW | G30: =G29 -> 2Q 62 26 00 00 00 00 | H30: =H29 -> 2Q | I30: =I29 -> 62 | J30: =J29 -> 26 | K30: =K29 -> 00 | L30: =L29 -> 00 | M30: =M29 -> 00 | N30: =N29 -> 00 | O30: =C30 & " | Insumo principal: " & F30 -> Escavação, carga e transporte em material de 1ª categoria - DMT de 200 a 400 m com motoscraper | Insumo principal: Motoscraper - 304 kW
B31: 5501713 | C31: Escavação, carga e transporte em material de 1ª categoria - DMT de 400 a 600 m com motoscraper | D31: =VLOOKUP(B31,CORRESPONDENCIA!$C$4:$F$2105,2,0) -> 2.6.1 | E31: E9523 | F31: Motoscraper - 304 kW | G31: =G30 -> 2Q 62 26 00 00 00 00 | H31: =H30 -> 2Q | I31: =I30 -> 62 | J31: =J30 -> 26 | K31: =K30 -> 00 | L31: =L30 -> 00 | M31: =M30 -> 00 | N31: =N30 -> 00 | O31: =C31 & " | Insumo principal: " & F31 -> Escavação, carga e transporte em material de 1ª categoria - DMT de 400 a 600 m com motoscraper | Insumo principal: Motoscraper - 304 kW
B32: 5501711 | C32: Escavação, carga e transporte em material de 1ª categoria - DMT de 50 a 200 m com motoscraper | D32: =VLOOKUP(B32,CORRESPONDENCIA!$C$4:$F$2105,2,0) -> 2.6.1 | E32: E9523 | F32: Motoscraper - 304 kW | G32: =G31 -> 2Q 62 26 00 00 00 00 | H32: =H31 -> 2Q | I32: =I31 -> 62 | J32: =J31 -> 26 | K32: =K31 -> 00 | L32: =L31 -> 00 | M32: =M31 -> 00 | N32: =N31 -> 00 | O32: =C32 & " | Insumo principal: " & F32 -> Escavação, carga e transporte em material de 1ª categoria - DMT de 50 a 200 m com motoscraper | Insumo principal: Motoscraper - 304 kW
B33: 5501714 | C33: Escavação, carga e transporte em material de 1ª categoria - DMT de 600 a 800 m com motoscraper | D33: =VLOOKUP(B33,CORRESPONDENCIA!$C$4:$F$2105,2,0) -> 2.6.1 | E33: E9523 | F33: Motoscraper - 304 kW | G33: =G32 -> 2Q 62 26 00 00 00 00 | H33: =H32 -> 2Q | I33: =I32 -> 62 | J33: =J32 -> 26 | K33: =K32 -> 00 | L33: =L32 -> 00 | M33: =M32 -> 00 | N33: =N32 -> 00 | O33: =C33 & " | Insumo principal: " & F33 -> Escavação, carga e transporte em material de 1ª categoria - DMT de 600 a 800 m com motoscraper | Insumo principal: Motoscraper - 304 kW
B34: 5501715 | C34: Escavação, carga e transporte em material de 1ª categoria - DMT de 800 a 1.000 m com motoscraper | D34: =VLOOKUP(B34,CORRESPONDENCIA!$C$4:$F$2105,2,0) -> 2.6.1 | E34: E9523 | F34: Motoscraper - 304 kW | G34: =G33 -> 2Q 62 26 00 00 00 00 | H34: =H33 -> 2Q | I34: =I33 -> 62 | J34: =J33 -> 26 | K34: =K33 -> 00 | L34: =L33 -> 00 | M34: =M33 -> 00 | N34: =N33 -> 00 | O34: =C34 & " | Insumo principal: " & F34 -> Escavação, carga e transporte em material de 1ª categoria - DMT de 800 a 1.000 m com motoscraper | Insumo principal: Motoscraper - 304 kW
B35: 5501710 | C35: Escavação e transporte de material de 1ªcategoriacomtratordeesteiras-DMTdeaté50m | D35: =VLOOKUP(B35,CORRESPONDENCIA!$C$4:$F$2105,2,0) -> 2.6.2 | E35: E9541 | F35: Trator sobre esteiras com lâmina - 259 kW | G35: ='insumos terrapl'!D3 -> 2Q 62 30 02 14 00 00 | H35: ='insumos terrapl'!E3 -> 2Q | I35: ='insumos terrapl'!F3 -> 62 | J35: ='insumos terrapl'!G3 -> 30 | K35: ='insumos terrapl'!H3 -> 02 | L35: ='insumos terrapl'!I3 -> 14 | M35: ='insumos terrapl'!J3 -> 00 | N35: ='insumos terrapl'!K3 -> 00 | O35: =C35 & " | Insumo principal: " & F35 -> Escavação e transporte de material de 1ªcategoriacomtratordeesteiras-DMTdeaté50m | Insumo principal: Trator sobre esteiras com lâmina - 259 kW
B36: 5501880 | C36: Escavação, carga e transporte de material de 1ª categoria - DMT de 1.000 a 1.200 m - caminho de serviço em leito natural - com carregadeira e caminhão basculante de 14 m³ | D36: =VLOOKUP(B36,CORRESPONDENCIA!$C$4:$F$2105,2,0) -> 2.6.3 | E36: E9667 | F36: Caminhão basculante com capacidade de 14 m³ - 210 kW | G36: ='insumos terrapl'!D32 -> 2Q 66 10 02 00 00 00 | H36: ='insumos terrapl'!E32 -> 2Q | I36: ='insumos terrapl'!F32 -> 66 | J36: ='insumos terrapl'!G32 -> 10 | K36: ='insumos terrapl'!H32 -> 02 | L36: ='insumos terrapl'!I32 -> 00 | M36: ='insumos terrapl'!J32 -> 00 | N36: ='insumos terrapl'!K32 -> 00 | O36: =C36 & " | Insumo principal: " & F36 -> Escavação, carga e transporte de material de 1ª categoria - DMT de 1.000 a 1.200 m - caminho de serviço em leito natural - com carregadeira e caminhão basculante de 14 m³ | Insumo principal: Caminhão basculante com capacidade de 14 m³ - 210 kW
B37: 5501906 | C37: Escavação, carga e transporte de material de 1ª categoria - DMT de 1.000 a 1.200 m - caminho de serviço em revestimento primário - com carregadeira e caminhão basculante de 14 m³ | D37: =VLOOKUP(B37,CORRESPONDENCIA!$C$4:$F$2105,2,0) -> 2.6.3 | E37: E9667 | F37: Caminhão basculante com capacidade de 14 m³ - 210 kW | G37: =G36 -> 2Q 66 10 02 00 00 00 | H37: =H36 -> 2Q | I37: =I36 -> 66 | J37: =J36 -> 10 | K37: =K36 -> 02 | L37: =L36 -> 00 | M37: =M36 -> 00 | N37: =N36 -> 00 | O37: =C37 & " | Insumo principal: " & F37 -> Escavação, carga e transporte de material de 1ª categoria - DMT de 1.000 a 1.200 m - caminho de serviço em revestimento primário - com carregadeira e caminhão basculante de 14 m³ | Insumo principal: Caminhão basculante com capacidade de 14 m³ - 210 kW
B38: 5501932 | C38: Escavação, carga e transporte de material de 1ª categoria - DMT de 1.000 a 1.200 m - caminho de serviço pavimentado - com carregadeira e caminhão basculante de 14 m³ | D38: =VLOOKUP(B38,CORRESPONDENCIA!$C$4:$F$2105,2,0) -> 2.6.3 | E38: E9667 | F38: Caminhão basculante com capacidade de 14 m³ - 210 kW | G38: =G37 -> 2Q 66 10 02 00 00 00 | H38: =H37 -> 2Q | I38: =I37 -> 66 | J38: =J37 -> 10 | K38: =K37 -> 02 | L38: =L37 -> 00 | M38: =M37 -> 00 | N38: =N37 -> 00 | O38: =C38 & " | Insumo principal: " & F38 -> Escavação, carga e transporte de material de 1ª categoria - DMT de 1.000 a 1.200 m - caminho de serviço pavimentado - com carregadeira e caminhão basculante de 14 m³ | Insumo principal: Caminhão basculante com capacidade de 14 m³ - 210 kW
B39: 5501881 | C39: Escavação, carga e transporte de material de 1ª categoria - DMT de 1.200 a 1.400 m - caminho de serviço em leito natural - com carregadeira e caminhão basculante de 14 m³ | D39: =VLOOKUP(B39,CORRESPONDENCIA!$C$4:$F$2105,2,0) -> 2.6.3 | E39: E9667 | F39: Caminhão basculante com capacidade de 14 m³ - 210 kW | G39: =G38 -> 2Q 66 10 02 00 00 00 | H39: =H38 -> 2Q | I39: =I38 -> 66 | J39: =J38 -> 10 | K39: =K38 -> 02 | L39: =L38 -> 00 | M39: =M38 -> 00 | N39: =N38 -> 00 | O39: =C39 & " | Insumo principal: " & F39 -> Escavação, carga e transporte de material de 1ª categoria - DMT de 1.200 a 1.400 m - caminho de serviço em leito natural - com carregadeira e caminhão basculante de 14 m³ | Insumo principal: Caminhão basculante com capacidade de 14 m³ - 210 kW
B40: 5501907 | C40: Escavação, carga e transporte de material de 1ª categoria - DMT de 1.200 a 1.400 m - caminho de serviço em revestimento primário - com carregadeira e caminhão basculante de 14 m³ | D40: =VLOOKUP(B40,CORRESPONDENCIA!$C$4:$F$2105,2,0) -> 2.6.3 | E40: E9667 | F40: Caminhão basculante com capacidade de 14 m³ - 210 kW | G40: =G39 -> 2Q 66 10 02 00 00 00 | H40: =H39 -> 2Q | I40: =I39 -> 66 | J40: =J39 -> 10 | K40: =K39 -> 02 | L40: =L39 -> 00 | M40: =M39 -> 00 | N40: =N39 -> 00 | O40: =C40 & " | Insumo principal: " & F40 -> Escavação, carga e transporte de material de 1ª categoria - DMT de 1.200 a 1.400 m - caminho de serviço em revestimento primário - com carregadeira e caminhão basculante de 14 m³ | Insumo principal: Caminhão basculante com capacidade de 14 m³ - 210 kW
B41: 5501933 | C41: Escavação, carga e transporte de material de 1ª categoria - DMT de 1.200 a 1.400 m - caminho de serviço pavimentado - com carregadeira e caminhão basculante de 14 m³ | D41: =VLOOKUP(B41,CORRESPONDENCIA!$C$4:$F$2105,2,0) -> 2.6.3 | E41: E9667 | F41: Caminhão basculante com capacidade de 14 m³ - 210 kW | G41: =G40 -> 2Q 66 10 02 00 00 00 | H41: =H40 -> 2Q | I41: =I40 -> 66 | J41: =J40 -> 10 | K41: =K40 -> 02 | L41: =L40 -> 00 | M41: =M40 -> 00 | N41: =N40 -> 00 | O41: =C41 & " | Insumo principal: " & F41 -> Escavação, carga e transporte de material de 1ª categoria - DMT de 1.200 a 1.400 m - caminho de serviço pavimentado - com carregadeira e caminhão basculante de 14 m³ | Insumo principal: Caminhão basculante com capacidade de 14 m³ - 210 kW
B42: 5501882 | C42: Escavação, carga e transporte de material de 1ª categoria - DMT de 1.400 a 1.600 m - caminho de serviço em leito natural - com carregadeira e caminhão basculante de 14 m³ | D42: =VLOOKUP(B42,CORRESPONDENCIA!$C$4:$F$2105,2,0) -> 2.6.3 | E42: E9667 | F42: Caminhão basculante com capacidade de 14 m³ - 210 kW | G42: =G41 -> 2Q 66 10 02 00 00 00 | H42: =H41 -> 2Q | I42: =I41 -> 66 | J42: =J41 -> 10 | K42: =K41 -> 02 | L42: =L41 -> 00 | M42: =M41 -> 00 | N42: =N41 -> 00 | O42: =C42 & " | Insumo principal: " & F42 -> Escavação, carga e transporte de material de 1ª categoria - DMT de 1.400 a 1.600 m - caminho de serviço em leito natural - com carregadeira e caminhão basculante de 14 m³ | Insumo principal: Caminhão basculante com capacidade de 14 m³ - 210 kW
...
